This is the result of the test:

$ ./manage.py test my_app
Creating test database for alias 'default'...
.F
======================================================================
FAIL: test_sum (my_app.tests.SumTest)
----------------------------------------------------------------------
Traceback (most recent call last):
  File "/home/mark/projects/django-sum-bug.git/my_project/my_app/tests.py", line 55, in test_sum
    self.assertEqual(rows.aggregate(Sum('amount'))['amount__sum'], 30)
AssertionError: Decimal('40.00') != 30

----------------------------------------------------------------------
Ran 2 tests in 0.013s

FAILED (failures=1)
Destroying test database for alias 'default'...
